Workbook

Sheet Cover & Assumptions
B2: BENCHMARK ELECTRONICS, INC.
B3: 13-Week Cash Flow Forecast
B4: For the Period FY2022 → FY2025
B5: Historical Financial Data | C5: FY2022 | D5: FY2023 | E5: FY2024 | F5: FY2025
B6: Revenue ($000s) | C6: ='Financial Statements'!C6 -> 2886331 | D6: ='Financial Statements'!D6 -> 2838976 | E6: ='Financial Statements'!E6 -> 2656105 | F6: ='Financial Statements'!F6 -> 2659108
B7: Cost of Sales ($000s) | C7: ='Financial Statements'!C7 -> 2631096 | D7: ='Financial Statements'!D7 -> 2567906 | E7: ='Financial Statements'!E7 -> 2386081 | F7: ='Financial Statements'!F7 -> 2389044
B8: Gross Profit ($000s) | C8: ='Financial Statements'!C8 -> 255235 | D8: ='Financial Statements'!D8 -> 271070 | E8: ='Financial Statements'!E8 -> 270024 | F8: ='Financial Statements'!F8 -> 270064
B9: Gross Margin % | C9: =C8/C6 -> 0.088428874 | D9: =D8/D6 -> 0.09548161 | E9: =E8/E6 -> 0.10166164 | F9: =F8/F6 -> 0.10156188
B10: Operating Cash Flow ($000s) | C10: ='Financial Statements'!C72 -> -177467 | D10: ='Financial Statements'!D72 -> 174294 | E10: ='Financial Statements'!E72 -> 189225 | F10: ='Financial Statements'!F72 -> 123964
B11: Capital Expenditures ($000s) | C11: =ABS('Financial Statements'!C76) -> 46774 | D11: =ABS('Financial Statements'!D76) -> 77739 | E11: =ABS('Financial Statements'!E76) -> 33253 | F11: =ABS('Financial Statements'!F76) -> 38544
B12: Cash & Equivalents ($000s) | C12: ='Financial Statements'!C32 -> 207430 | D12: ='Financial Statements'!D32 -> 277391 | E12: ='Financial Statements'!E32 -> 315152 | F12: ='Financial Statements'!F32 -> 322064
B13: Accounts Receivable ($000s) | C13: ='Financial Statements'!C34 -> 491957 | D13: ='Financial Statements'!D34 -> 449404 | E13: ='Financial Statements'!E34 -> 412458 | F13: ='Financial Statements'!F34 -> 391101
B14: Inventories ($000s) | C14: ='Financial Statements'!C36 -> 727749 | D14: ='Financial Statements'!D36 -> 683801 | E14: ='Financial Statements'!E36 -> 553654 | F14: ='Financial Statements'!F36 -> 482544
B15: Accounts Payable ($000s) | C15: ='Financial Statements'!C48 -> 424272 | D15: ='Financial Statements'!D48 -> 367480 | E15: ='Financial Statements'!E48 -> 354218 | F15: ='Financial Statements'!F48 -> 403222
B16: Days Sales Outstanding (DSO) | C16: =C13/(C6/365) -> 62.211959 | D16: =D13/(D6/365) -> 57.778741 | E16: =E13/(E6/365) -> 56.679676 | F16: =F13/(F6/365) -> 53.684117
B17: Days Inventory Outstanding (DIO) | C17: =C14/(C7/365) -> 100.95731 | D17: =D14/(D7/365) -> 97.194899 | E17: =E14/(E7/365) -> 84.692728 | F17: =F14/(F7/365) -> 73.723448
B18: Days Payable Outstanding (DPO) | C18: =C15/(C7/365) -> 58.857328 | D18: =D15/(D7/365) -> 52.233298 | E18: =E15/(E7/365) -> 54.184904 | F18: =F15/(F7/365) -> 61.604571
B20: Scenario Descriptions
B21: Base Case
B22: Operations perform in line with FY2025 historical run-rates. DSO ~53 days, DIO ~74 days, DPO ~62 days.
B23: Scenario 1 – Slower Collections
B24: Customer payments slow by ~15 days (DSO rises to ~69 days), reflecting tightening credit conditions in key end-markets (aerospace & defense, industrial). Inventory stays flat. AP terms unchanged. Models liquidity pressure from AR drag.
B25: Scenario 2 – Seasonal Cash Pressure
B26: Q1 demand softness typical in electronics manufacturing: revenue -8% vs base, DIO is +10% (73.7 to 81.1 days). Because revenue is also down 8%, inventory dollars only rise about 1.2% ($483.9M to $489.7M). Collections also slow modestly (+7 days DSO).
B27: Scenario 3 – Process Improvement
B28: Electronic documentation & ERP optimization reduces DSO by 8 days and DPO extends by 5 days through better AP scheduling. Models cash benefit of operational efficiency initiatives over 13 weeks.

Sheet Financial Statements
B2: BENCHMARK ELECTRONICS, INC.
B3: Financial Statements (in $000s)
C4: FY2022 | D4: FY2023 | E4: FY2024 | F4: FY2025 | G4: FY2026
B5: CONSOLIDATED STATEMENTS OF INCOME
B6: Sales | C6: 2886331 | D6: 2838976 | E6: 2656105 | F6: 2659108
B7: Cost of Sales | C7: 2631096 | D7: 2567906 | E7: 2386081 | F7: 2389044
B8: Gross Profit | C8: =C6-C7 -> 255235 | D8: =D6-D7 -> 271070 | E8: =E6-E7 -> 270024 | F8: =F6-F7 -> 270064
B9: Gross Margin % | C9: =C8/C6 -> 0.088428874 | D9: =D8/D6 -> 0.09548161 | E9: =E8/E6 -> 0.10166164 | F9: =F8/F6 -> 0.10156188
B10: SG&A Expenses | C10: 150215 | D10: 147025 | E10: 149460 | F10: 159658
B11: Amortization of Intangible Assets | C11: 6384 | D11: 5979 | E11: 4817 | F11: 4817
B12: Restructuring & Other Costs | C12: 8567 | D12: 8402 | E12: 6336 | F12: 29540
B13: Total Operating Expenses | C13: =C10+C11+C12 -> 165166 | D13: =D10+D11+D12 -> 161406 | E13: =E10+E11+E12 -> 160613 | F13: =F10+F11+F12 -> 194015
B14: Income from Operations (EBIT) | C14: =C8-C13 -> 90069 | D14: =D8-D13 -> 109664 | E14: =E8-E13 -> 109411 | F14: =F8-F13 -> 76049
B15: EBIT Margin % | C15: =C14/C6 -> 0.031205361 | D15: =D14/D6 -> 0.038628012 | E15: =E14/E6 -> 0.041192272 | F15: =F14/F6 -> 0.02859944
B16: Interest Expense | C16: -12894 | D16: -31875 | E16: -26922 | F16: -20158
B17: Interest Income | C17: 1730 | D17: 6256 | E17: 10208 | F17: 9552
B18: Other Expense, net | C18: 5437 | D18: -2825 | E18: -8802 | F18: -3909
B19: Income Before Taxes (EBT) | C19: =C14+C16+C17+C18 -> 84342 | D19: =D14+D16+D17+D18 -> 81220 | E19: =E14+E16+E17+E18 -> 83895 | F19: =F14+F16+F17+F18 -> 61534
B20: Income Tax Expense | C20: 16113 | D20: 12277 | E20: 22769 | F20: 36682
B21: Effective Tax Rate % | C21: =IF(C19=0,0,C20/C19) -> 0.19104361 | D21: =IF(D19=0,0,D20/D19) -> 0.15115735 | E21: =IF(E19=0,0,E20/E19) -> 0.27139877 | F21: =IF(F19=0,0,F20/F19) -> 0.59612572
B22: Net Income | C22: =C19-C20 -> 68229 | D22: =D19-D20 -> 68943 | E22: =E19-E20 -> 61126 | F22: =F19-F20 -> 24852
B23: Net Margin % | C23: =C22/C6 -> 0.023638661 | D23: =D22/D6 -> 0.02428446 | E23: =E22/E6 -> 0.023013397 | F23: =F22/F6 -> 0.0093459912
B24: Basic EPS | C24: 1.94 | D24: 1.94 | E24: 1.7 | F24: 0.69
B25: Diluted EPS | C25: 1.91 | D25: 1.92 | E25: 1.66 | F25: 0.68
B26: Basic Shares Outstanding (000s) | C26: 35179 | D26: 35566 | E26: 35970 | F26: 35879
B27: Diluted Shares Outstanding (000s) | C27: 35718 | D27: 35973 | E27: 36759 | F27: 36300
B29: CONSOLIDATED BALANCE SHEETS
B30: ASSETS
B31: Current Assets
B32: Cash & Cash Equivalents | C32: 207430 | D32: 277391 | E32: 315152 | F32: 322064
B33: Restricted Cash | C33: 0 | D33: 5822 | E33: 12875 | F33: 336
B34: Accounts Receivable, net | C34: 491957 | D34: 449404 | E34: 412458 | F34: 391101
B35: Contract Assets | C35: 183613 | D35: 174979 | E35: 167578 | F35: 182870
B36: Inventories | C36: 727749 | D36: 683801 | E36: 553654 | F36: 482544
B37: Prepaid & Other Current Assets | C37: 41400 | D37: 44350 | E37: 44720 | F37: 69226
B38: Total Current Assets | C38: =SUM(C32:C37) -> 1652149 | D38: =SUM(D32:D37) -> 1635747 | E38: 1506437 | F38: 1448141
B39: Property, Plant & Equipment, net | C39: 211478 | D39: 227698 | E39: 225097 | F39: 223784
B40: Operating Lease ROU Assets | C40: 93081 | D40: 130830 | E40: 117995 | F40: 102664
B41: Goodwill | C41: 192116 | D41: 192116 | E41: 192116 | F41: 192116
B42: Deferred Income Taxes | C42: 12235 | D42: 26943 | E42: 26664 | F42: 34936
...

Sheet Working Capital Trend Analysis
A1: BENCHMARK ELECTRONICS, INC.
A2: Working Capital Trend Analysis (FY2022 → FY2025)
B3: FY2022 | C3: FY2023 | D3: FY2024 | E3: FY2025 | F3: Average | G3: Trend | H3: What This Means for Cash Forecasting
A4: Days Sales Outstanding (DSO) | B4: ='Financial Statements'!C92 -> 62.211959 | C4: ='Financial Statements'!D92 -> 57.778741 | D4: ='Financial Statements'!E92 -> 56.679676 | E4: ='Financial Statements'!F92 -> 53.684117 | F4: =IFERROR(AVERAGE(B4:E4),0) -> 57.588623 | G4: ▼ Improving | H4: DSO declining → customers paying faster → positive for cash. Base case assumption of 53.7 days reflects FY2025 actual trend.
A5: Average | B5: =+$F$4 -> 57.588623 | C5: =+$F$4 -> 57.588623 | D5: =+$F$4 -> 57.588623 | E5: =+$F$4 -> 57.588623
A6: Days Inventory Outstanding (DIO) | B6: ='Financial Statements'!C93 -> 100.95731 | C6: ='Financial Statements'!D93 -> 97.194899 | D6: ='Financial Statements'!E93 -> 84.692728 | E6: ='Financial Statements'!F93 -> 73.723448 | F6: =IFERROR(AVERAGE(B6:E6),0) -> 89.142097 | G6: ▼ Improving | H6: Inventory turning faster → less cash tied up in stock. Improvement from 101.0→73.7 days for the full period signals better demand-supply matching.
A7: Average | B7: =$F$6 -> 89.142097 | C7: =$F$6 -> 89.142097 | D7: =$F$6 -> 89.142097 | E7: =$F$6 -> 89.142097
A8: Days Payable Outstanding (DPO) | B8: ='Financial Statements'!C94 -> 58.857328 | C8: ='Financial Statements'!D94 -> 52.233298 | D8: ='Financial Statements'!E94 -> 54.184904 | E8: ='Financial Statements'!F94 -> 61.604571 | F8: =IFERROR(AVERAGE(B8:E8),0) -> 56.720025 | G8: ▲ Improving | H8: BHE paying suppliers more slowly → retaining cash longer. Rising DPO is favorable; Scenario 3 extends this further +5 days.
A9: Average | B9: =$F$8 -> 56.720025 | C9: =$F$8 -> 56.720025 | D9: =$F$8 -> 56.720025 | E9: =$F$8 -> 56.720025
A10: Cash Conversion Cycle | B10: =B4+B6-B8 -> 104.31194 | C10: =C4+C6-C8 -> 102.74034 | D10: =D4+D6-D8 -> 87.1875 | E10: =E4+E6-E8 -> 65.802994 | F10: =IFERROR(AVERAGE(B10:E10),0) -> 90.010695 | G10: ▼ Improving | H10: CCC = days cash is tied up in operations. Declining CCC = BHE converting revenue to cash more efficiently each year.
A11: Average | B11: =$F$10 -> 90.010695 | C11: =$F$10 -> 90.010695 | D11: =$F$10 -> 90.010695 | E11: =$F$10 -> 90.010695
A12: Gross Margin % | B12: ='Financial Statements'!C8/'Financial Statements'!C6 -> 0.088428874 | C12: ='Financial Statements'!D8/'Financial Statements'!D6 -> 0.09548161 | D12: ='Financial Statements'!E8/'Financial Statements'!E6 -> 0.10166164 | E12: ='Financial Statements'!F8/'Financial Statements'!F6 -> 0.10156188 | F12: =IFERROR(AVERAGE(B12:E12),0) -> 0.096783501 | G12: ▲ Stable | H12: Margin stable~10% despite revenue fluctuation. Validates use of 89.84% COGS assumption across all scenarios.
A13: Average | B13: =$F$12 -> 0.096783501 | C13: =$F$12 -> 0.096783501 | D13: =$F$12 -> 0.096783501 | E13: =$F$12 -> 0.096783501
A14: Operating Cash Flow ($000s) | B14: ='Financial Statements'!C72 -> -177467 | C14: ='Financial Statements'!D72 -> 174294 | D14: ='Financial Statements'!E72 -> 189225 | E14: ='Financial Statements'!F72 -> 123964 | F14: =IFERROR(AVERAGE(B14:E14),0) -> 77504 | G14: ▲ Recovered | H14: OCF recovered from a cash burn year (FY2022) driven by the inventory build (DIO peaked at 101 days), with FY2025 pulling back from the FY2024 high.
A15: Average | B15: =$F$14 -> 77504 | C15: =$F$14 -> 77504 | D15: =$F$14 -> 77504 | E15: =$F$14 -> 77504
A16: CapEx ($000s) | B16: =-'Financial Statements'!C76 -> 46774 | C16: =-'Financial Statements'!D76 -> 77739 | D16: =-'Financial Statements'!E76 -> 33253 | E16: =-'Financial Statements'!F76 -> 38544 | F16: =IFERROR(AVERAGE(B16:E16),0) -> 49077.5 | G16: ► Normalizing | H16: CapEx peaked at $77.7M in FY2023, fell 57% to $33.3M in FY2024, then rose 16% to $38.5M in FY2025 (50% below peak). Base case uses the FY2025 total of $38.5M/yr ($741K/week). Scenario 2 cuts this 30% to ~$27M/yr, reflecting typical capex deferral during soft quarters.
A17: Average | B17: =$F$16 -> 49077.5 | C17: =$F$16 -> 49077.5 | D17: =$F$16 -> 49077.5 | E17: =$F$16 -> 49077.5
A19: Charts

Sheet Base Case
B2: BENCHMARK ELECTRONICS, INC.
B3: BASE CASE | 13-WEEK CASH FLOW FORECAST
C4: Opening Balance | D4: Week 1 | E4: Week 2 | F4: Week 3 | G4: Week 4 | H4: Week 5 | I4: Week 6 | J4: Week 7 | K4: Week 8 | L4: Week 9 | M4: Week 10 | N4: Week 11 | O4: Week 12 | P4: Week 13 | Q4: 13-Wk Total
B5: KEY ASSUMPTIONS
B6: Weekly Revenue ($000s) | C6: - | D6: ='Financial Statements'!$F$97 -> 51136.692 | E6: ='Financial Statements'!$F$97 -> 51136.692 | F6: ='Financial Statements'!$F$97 -> 51136.692 | G6: ='Financial Statements'!$F$97 -> 51136.692 | H6: ='Financial Statements'!$F$97 -> 51136.692 | I6: ='Financial Statements'!$F$97 -> 51136.692 | J6: ='Financial Statements'!$F$97 -> 51136.692 | K6: ='Financial Statements'!$F$97 -> 51136.692 | ... P6: ='Financial Statements'!$F$97 -> 51136.692
B7: DSO (days) | C7: - | D7: ='Financial Statements'!$F$92 -> 53.684117 | E7: ='Financial Statements'!$F$92 -> 53.684117 | F7: ='Financial Statements'!$F$92 -> 53.684117 | G7: ='Financial Statements'!$F$92 -> 53.684117 | H7: ='Financial Statements'!$F$92 -> 53.684117 | I7: ='Financial Statements'!$F$92 -> 53.684117 | J7: ='Financial Statements'!$F$92 -> 53.684117 | K7: ='Financial Statements'!$F$92 -> 53.684117 | ... P7: ='Financial Statements'!$F$92 -> 53.684117
B8: DIO (days) | C8: - | D8: ='Financial Statements'!$F$93 -> 73.723448 | E8: ='Financial Statements'!$F$93 -> 73.723448 | F8: ='Financial Statements'!$F$93 -> 73.723448 | G8: ='Financial Statements'!$F$93 -> 73.723448 | H8: ='Financial Statements'!$F$93 -> 73.723448 | I8: ='Financial Statements'!$F$93 -> 73.723448 | J8: ='Financial Statements'!$F$93 -> 73.723448 | K8: ='Financial Statements'!$F$93 -> 73.723448 | ... P8: ='Financial Statements'!$F$93 -> 73.723448
B9: DPO (days) | C9: - | D9: ='Financial Statements'!$F$94 -> 61.604571 | E9: ='Financial Statements'!$F$94 -> 61.604571 | F9: ='Financial Statements'!$F$94 -> 61.604571 | G9: ='Financial Statements'!$F$94 -> 61.604571 | H9: ='Financial Statements'!$F$94 -> 61.604571 | I9: ='Financial Statements'!$F$94 -> 61.604571 | J9: ='Financial Statements'!$F$94 -> 61.604571 | K9: ='Financial Statements'!$F$94 -> 61.604571 | ... P9: ='Financial Statements'!$F$94 -> 61.604571
B10: Weekly CapEx ($000s) | C10: - | D10: ='Financial Statements'!$F$99 -> 741.23077 | E10: ='Financial Statements'!$F$99 -> 741.23077 | F10: ='Financial Statements'!$F$99 -> 741.23077 | G10: ='Financial Statements'!$F$99 -> 741.23077 | H10: ='Financial Statements'!$F$99 -> 741.23077 | I10: ='Financial Statements'!$F$99 -> 741.23077 | J10: ='Financial Statements'!$F$99 -> 741.23077 | K10: ='Financial Statements'!$F$99 -> 741.23077 | ... P10: ='Financial Statements'!$F$99 -> 741.23077
B11: CASH RECEIPTS
B12: Cash Collections from Customers | C12: - | D12: =IF(D7=0,0,C13/D7*7) -> 50996.592 | E12: =IF(E7=0,0,D13/E7*7) -> 51014.86 | F12: =IF(F7=0,0,E13/F7*7) -> 51030.746 | G12: =IF(G7=0,0,F13/G7*7) -> 51044.56 | H12: =IF(H7=0,0,G13/H7*7) -> 51056.574 | I12: =IF(I7=0,0,H13/I7*7) -> 51067.021 | J12: =IF(J7=0,0,I13/J7*7) -> 51076.105 | K12: =IF(K7=0,0,J13/K7*7) -> 51084.005 | ... P12: =IF(P7=0,0,O13/P7*7) -> 51110.491 | Q12: =SUM(D12:P12) -> 663877.29
B13: Accounts Receivable (Ending) | C13: ='Financial Statements'!F34 -> 391101 | D13: =C13+D6-D12 -> 391241.1 | E13: =D13+E6-E12 -> 391362.93 | F13: =E13+F6-F12 -> 391468.88 | G13: =F13+G6-G12 -> 391561.01 | H13: =G13+H6-H12 -> 391641.13 | I13: =H13+I6-I12 -> 391710.8 | J13: =I13+J6-J12 -> 391771.39 | K13: =J13+K6-K12 -> 391824.08 | ... P13: =O13+P6-P12 -> 392000.71 | Q13: =P13 -> 392000.71
B15: Total Cash Receipts | C15: - | D15: =D12 -> 50996.592 | E15: =E12 -> 51014.86 | F15: =F12 -> 51030.746 | G15: =G12 -> 51044.56 | H15: =H12 -> 51056.574 | I15: =I12 -> 51067.021 | J15: =J12 -> 51076.105 | K15: =K12 -> 51084.005 | ... P15: =P12 -> 51110.491 | Q15: =SUM(D15:P15) -> 663877.29
B16: CASH DISBURSEMENTS
B17: Inventory (Ending) | C17: ='Financial Statements'!F36 -> 482544 | D17: =(D6*'Financial Statements'!$F$96)/7*'Base Case'!D8 -> 483869.67 | E17: =(E6*'Financial Statements'!$F$96)/7*'Base Case'!E8 -> 483869.67 | F17: =(F6*'Financial Statements'!$F$96)/7*'Base Case'!F8 -> 483869.67 | G17: =(G6*'Financial Statements'!$F$96)/7*'Base Case'!G8 -> 483869.67 | H17: =(H6*'Financial Statements'!$F$96)/7*'Base Case'!H8 -> 483869.67 | I17: =(I6*'Financial Statements'!$F$96)/7*'Base Case'!I8 -> 483869.67 | J17: =(J6*'Financial Statements'!$F$96)/7*'Base Case'!J8 -> 483869.67 | K17: =(K6*'Financial Statements'!$F$96)/7*'Base Case'!K8 -> 483869.67 | ... P17: =(P6*'Financial Statements'!$F$96)/7*'Base Case'!P8 -> 483869.67 | Q17: =P17 -> 483869.67
B18: Inventory Purchases | C18: - | D18: =(D6*'Financial Statements'!$F$96)+D17-C17 -> 47268.824 | E18: =(E6*'Financial Statements'!$F$96)+E17-D17 -> 45943.154 | F18: =(F6*'Financial Statements'!$F$96)+F17-E17 -> 45943.154 | G18: =(G6*'Financial Statements'!$F$96)+G17-F17 -> 45943.154 | H18: =(H6*'Financial Statements'!$F$96)+H17-G17 -> 45943.154 | I18: =(I6*'Financial Statements'!$F$96)+I17-H17 -> 45943.154 | J18: =(J6*'Financial Statements'!$F$96)+J17-I17 -> 45943.154 | K18: =(K6*'Financial Statements'!$F$96)+K17-J17 -> 45943.154 | ... P18: =(P6*'Financial Statements'!$F$96)+P17-O17 -> 45943.154 | Q18: =SUM(D18:P18) -> 598586.67
B19: Accounts Payable (Ending) | C19: ='Financial Statements'!F48 -> 403222 | D19: =C19+D18-D20 -> 404673.54 | E19: =D19+E18-E20 -> 404634.48 | F19: =E19+F18-F20 -> 404599.85 | G19: =F19+G18-G20 -> 404569.16 | H19: =G19+H18-H20 -> 404541.96 | I19: =H19+I18-I20 -> 404517.85 | J19: =I19+J18-J20 -> 404496.47 | K19: =J19+K18-K20 -> 404477.53 | ... P19: =O19+P18-P20 -> 404410.6 | Q19: =P19 -> 404410.6
B20: AP Payments to Suppliers | C20: - | D20: =C19/D9*7 -> 45817.282 | E20: =D19/E9*7 -> 45982.218 | F20: =E19/F9*7 -> 45977.779 | G20: =F19/G9*7 -> 45973.845 | H20: =G19/H9*7 -> 45970.357 | I20: =H19/I9*7 -> 45967.266 | J20: =I19/J9*7 -> 45964.526 | K20: =J19/K9*7 -> 45962.098 | ... P20: =O19/P9*7 -> 45953.518 | Q20: =SUM(D20:P20) -> 597398.07
B21: Operating Expenses (SG&A) | C21: - | D21: =D6*'Financial Statements'!$F$102 -> 3070.3462 | E21: =E6*'Financial Statements'!$F$102 -> 3070.3462 | F21: =F6*'Financial Statements'!$F$102 -> 3070.3462 | G21: =G6*'Financial Statements'!$F$102 -> 3070.3462 | H21: =H6*'Financial Statements'!$F$102 -> 3070.3462 | I21: =I6*'Financial Statements'!$F$102 -> 3070.3462 | J21: =J6*'Financial Statements'!$F$102 -> 3070.3462 | K21: =K6*'Financial Statements'!$F$102 -> 3070.3462 | ... P21: =P6*'Financial Statements'!$F$102 -> 3070.3462 | Q21: =SUM(D21:P21) -> 39914.5
B22: Interest Expense | C22: - | D22: ='Financial Statements'!$F$100 -> 387.65385 | E22: ='Financial Statements'!$F$100 -> 387.65385 | F22: ='Financial Statements'!$F$100 -> 387.65385 | G22: ='Financial Statements'!$F$100 -> 387.65385 | H22: ='Financial Statements'!$F$100 -> 387.65385 | I22: ='Financial Statements'!$F$100 -> 387.65385 | J22: ='Financial Statements'!$F$100 -> 387.65385 | K22: ='Financial Statements'!$F$100 -> 387.65385 | ... P22: ='Financial Statements'!$F$100 -> 387.65385 | Q22: =SUM(D22:P22) -> 5039.5
B23: Income Tax Payments | C23: - | D23: 0 | E23: 0 | F23: 0 | G23: ='Financial Statements'!$F$20/52*3 -> 2116.2692 | H23: 0 | I23: 0 | J23: ='Financial Statements'!$F$20/52*3 -> 2116.2692 | K23: 0 | L23: 0 | M23: ='Financial Statements'!$F$20/52*3 -> 2116.2692 | N23: 0 | O23: 0 | P23: ='Financial Statements'!$F$20/52*3 -> 2116.2692 | Q23: =SUM(D23:P23) -> 8465.0769
B24: Capital Expenditures | C24: - | D24: =D10 -> 741.23077 | E24: =E10 -> 741.23077 | F24: =F10 -> 741.23077 | G24: =G10 -> 741.23077 | H24: =H10 -> 741.23077 | I24: =I10 -> 741.23077 | J24: =J10 -> 741.23077 | K24: =K10 -> 741.23077 | ... P24: =P10 -> 741.23077 | Q24: =SUM(D24:P24) -> 9636
B25: Total Cash Disbursements | C25: - | D25: =D20+D21+D22+D23+D24 -> 50016.513 | E25: =E20+E21+E22+E23+E24 -> 50181.449 | F25: =F20+F21+F22+F23+F24 -> 50177.01 | G25: =G20+G21+G22+G23+G24 -> 52289.345 | H25: =H20+H21+H22+H23+H24 -> 50169.588 | I25: =I20+I21+I22+I23+I24 -> 50166.497 | J25: =J20+J21+J22+J23+J24 -> 52280.026 | K25: =K20+K21+K22+K23+K24 -> 50161.329 | ... P25: =P20+P21+P22+P23+P24 -> 52269.018 | Q25: =SUM(D25:P25) -> 660453.14
B26: CASH POSITION SUMMARY
B27: Net Cash Flow | D27: =D15-D25 -> 980.07882 | E27: =E15-E25 -> 833.41115 | F27: =F15-F25 -> 853.73594 | G27: =G15-G25 -> -1244.7843 | H27: =H15-H25 -> 886.98559 | I27: =I15-I25 -> 900.52352 | J27: =J15-J25 -> -1203.9212 | K27: =K15-K25 -> 922.67665 | ... P27: =P15-P25 -> -1158.5273 | Q27: =SUM(D27:P27) -> 3424.1425
B28: Beginning Cash Balance | C28: ='Financial Statements'!F32 -> 322064 | D28: =C28 -> 322064 | E28: =D29 -> 323044.08 | F28: =E29 -> 323877.49 | G28: =F29 -> 324731.23 | H28: =G29 -> 323486.44 | I28: =H29 -> 324373.43 | J28: =I29 -> 325273.95 | K28: =J29 -> 324070.03 | L28: =K29 -> 324992.71 | ... P28: =O29 -> 326646.67 | Q28: =D28 -> 322064
B29: Ending Cash Balance | D29: =D28+D27 -> 323044.08 | E29: =E28+E27 -> 323877.49 | F29: =F28+F27 -> 324731.23 | G29: =G28+G27 -> 323486.44 | H29: =H28+H27 -> 324373.43 | I29: =I28+I27 -> 325273.95 | J29: =J28+J27 -> 324070.03 | K29: =K28+K27 -> 324992.71 | ... P29: =P28+P27 -> 325488.14 | Q29: =P29 -> 325488.14
B30: Minimum Cash Buffer ($15,000K) | C30: 15000 | D30: 15000 | E30: 15000 | F30: 15000 | G30: 15000 | H30: 15000 | I30: 15000 | J30: 15000 | K30: 15000 | L30: 15000 | M30: 15000 | N30: 15000 | O30: 15000 | P30: 15000
B31: Cash Headroom vs. Minimum Buffer | D31: =D29-D30 -> 308044.08 | E31: =E29-E30 -> 308877.49 | F31: =F29-F30 -> 309731.23 | G31: =G29-G30 -> 308486.44 | H31: =H29-H30 -> 309373.43 | I31: =I29-I30 -> 310273.95 | J31: =J29-J30 -> 309070.03 | K31: =K29-K30 -> 309992.71 | ... P31: =P29-P30 -> 310488.14 | Q31: =P31 -> 310488.14

Sheet Scenario 1-Slow Collections
B2: BENCHMARK ELECTRONICS, INC.
B3: SCENARIO 1 — SLOWER COLLECTIONS (+15 DSO Days) (in $000s)
C4: Opening Balance | D4: Week 1 | E4: Week 2 | F4: Week 3 | G4: Week 4 | H4: Week 5 | I4: Week 6 | J4: Week 7 | K4: Week 8 | L4: Week 9 | M4: Week 10 | N4: Week 11 | O4: Week 12 | P4: Week 13 | Q4: 13-Wk Total
B5: KEY ASSUMPTIONS
B6: Weekly Revenue ($000s) | C6: - | D6: ='Base Case'!D6 -> 51136.692 | E6: ='Base Case'!E6 -> 51136.692 | F6: ='Base Case'!F6 -> 51136.692 | G6: ='Base Case'!G6 -> 51136.692 | H6: ='Base Case'!H6 -> 51136.692 | I6: ='Base Case'!I6 -> 51136.692 | J6: ='Base Case'!J6 -> 51136.692 | K6: ='Base Case'!K6 -> 51136.692 | ... P6: ='Base Case'!P6 -> 51136.692
B7: DSO (days) | C7: - | D7: ='Base Case'!D7+15 -> 68.684117 | E7: ='Base Case'!E7+15 -> 68.684117 | F7: ='Base Case'!F7+15 -> 68.684117 | G7: ='Base Case'!G7+15 -> 68.684117 | H7: ='Base Case'!H7+15 -> 68.684117 | I7: ='Base Case'!I7+15 -> 68.684117 | J7: ='Base Case'!J7+15 -> 68.684117 | K7: ='Base Case'!K7+15 -> 68.684117 | ... P7: ='Base Case'!P7+15 -> 68.684117
B8: DIO (days) | C8: - | D8: ='Base Case'!D8 -> 73.723448 | E8: ='Base Case'!E8 -> 73.723448 | F8: ='Base Case'!F8 -> 73.723448 | G8: ='Base Case'!G8 -> 73.723448 | H8: ='Base Case'!H8 -> 73.723448 | I8: ='Base Case'!I8 -> 73.723448 | J8: ='Base Case'!J8 -> 73.723448 | K8: ='Base Case'!K8 -> 73.723448 | ... P8: ='Base Case'!P8 -> 73.723448
B9: DPO (days) | C9: - | D9: ='Base Case'!D9 -> 61.604571 | E9: ='Base Case'!E9 -> 61.604571 | F9: ='Base Case'!F9 -> 61.604571 | G9: ='Base Case'!G9 -> 61.604571 | H9: ='Base Case'!H9 -> 61.604571 | I9: ='Base Case'!I9 -> 61.604571 | J9: ='Base Case'!J9 -> 61.604571 | K9: ='Base Case'!K9 -> 61.604571 | ... P9: ='Base Case'!P9 -> 61.604571
B10: Weekly CapEx ($000s) | C10: - | D10: ='Base Case'!D10 -> 741.23077 | E10: ='Base Case'!E10 -> 741.23077 | F10: ='Base Case'!F10 -> 741.23077 | G10: ='Base Case'!G10 -> 741.23077 | H10: ='Base Case'!H10 -> 741.23077 | I10: ='Base Case'!I10 -> 741.23077 | J10: ='Base Case'!J10 -> 741.23077 | K10: ='Base Case'!K10 -> 741.23077 | ... P10: ='Base Case'!P10 -> 741.23077
B11: CASH RECEIPTS
B12: Cash Collections from Customers | C12: - | D12: =IF(D7=0,0,C13/D7*7) -> 39859.39 | E12: =IF(E7=0,0,D13/E7*7) -> 41008.726 | F12: =IF(F7=0,0,E13/F7*7) -> 42040.926 | G12: =IF(G7=0,0,F13/G7*7) -> 42967.929 | H12: =IF(H7=0,0,G13/H7*7) -> 43800.455 | I12: =IF(I7=0,0,H13/I7*7) -> 44548.134 | J12: =IF(J7=0,0,I13/J7*7) -> 45219.613 | K12: =IF(K7=0,0,J13/K7*7) -> 45822.657 | ... P12: =IF(P7=0,0,O13/P7*7) -> 48032.064 | Q12: =SUM(D12:P12) -> 581481.96
B13: Accounts Receivable (Ending) | C13: ='Financial Statements'!F34 -> 391101 | D13: =C13+D6-D12 -> 402378.3 | E13: =D13+E6-E12 -> 412506.27 | F13: =E13+F6-F12 -> 421602.04 | G13: =F13+G6-G12 -> 429770.8 | H13: =G13+H6-H12 -> 437107.04 | I13: =H13+I6-I12 -> 443695.59 | J13: =I13+J6-J12 -> 449612.67 | K13: =J13+K6-K12 -> 454926.71 | ... P13: =O13+P6-P12 -> 474396.04 | Q13: =P13 -> 474396.04
B15: Total Cash Receipts | C15: - | D15: =D12 -> 39859.39 | E15: =E12 -> 41008.726 | F15: =F12 -> 42040.926 | G15: =G12 -> 42967.929 | H15: =H12 -> 43800.455 | I15: =I12 -> 44548.134 | J15: =J12 -> 45219.613 | K15: =K12 -> 45822.657 | ... P15: =P12 -> 48032.064 | Q15: =SUM(D15:P15) -> 581481.96
B16: CASH DISBURSEMENTS
B17: Inventory (Ending) | C17: ='Financial Statements'!F36 -> 482544 | D17: =(D6*'Financial Statements'!$F$96)/7*D8 -> 483869.67 | E17: =(E6*'Financial Statements'!$F$96)/7*E8 -> 483869.67 | F17: =(F6*'Financial Statements'!$F$96)/7*F8 -> 483869.67 | G17: =(G6*'Financial Statements'!$F$96)/7*G8 -> 483869.67 | H17: =(H6*'Financial Statements'!$F$96)/7*H8 -> 483869.67 | I17: =(I6*'Financial Statements'!$F$96)/7*I8 -> 483869.67 | J17: =(J6*'Financial Statements'!$F$96)/7*J8 -> 483869.67 | K17: =(K6*'Financial Statements'!$F$96)/7*K8 -> 483869.67 | ... P17: =(P6*'Financial Statements'!$F$96)/7*P8 -> 483869.67 | Q17: =P17 -> 483869.67
B18: Inventory Purchases | C18: - | D18: =(D6*'Financial Statements'!$F$96)+D17-C17 -> 47268.824 | E18: =(E6*'Financial Statements'!$F$96)+E17-D17 -> 45943.154 | F18: =(F6*'Financial Statements'!$F$96)+F17-E17 -> 45943.154 | G18: =(G6*'Financial Statements'!$F$96)+G17-F17 -> 45943.154 | H18: =(H6*'Financial Statements'!$F$96)+H17-G17 -> 45943.154 | I18: =(I6*'Financial Statements'!$F$96)+I17-H17 -> 45943.154 | J18: =(J6*'Financial Statements'!$F$96)+J17-I17 -> 45943.154 | K18: =(K6*'Financial Statements'!$F$96)+K17-J17 -> 45943.154 | ... P18: =(P6*'Financial Statements'!$F$96)+P17-O17 -> 45943.154 | Q18: =SUM(D18:P18) -> 598586.67
B19: Accounts Payable (Ending) | C19: ='Financial Statements'!F48 -> 403222 | D19: =C19+D18-D20 -> 404673.54 | E19: =D19+E18-E20 -> 404634.48 | F19: =E19+F18-F20 -> 404599.85 | G19: =F19+G18-G20 -> 404569.16 | H19: =G19+H18-H20 -> 404541.96 | I19: =H19+I18-I20 -> 404517.85 | J19: =I19+J18-J20 -> 404496.47 | K19: =J19+K18-K20 -> 404477.53 | ... P19: =O19+P18-P20 -> 404410.6 | Q19: =P19 -> 404410.6
B20: AP Payments to Suppliers | C20: - | D20: =C19/D9*7 -> 45817.282 | E20: =D19/E9*7 -> 45982.218 | F20: =E19/F9*7 -> 45977.779 | G20: =F19/G9*7 -> 45973.845 | H20: =G19/H9*7 -> 45970.357 | I20: =H19/I9*7 -> 45967.266 | J20: =I19/J9*7 -> 45964.526 | K20: =J19/K9*7 -> 45962.098 | ... P20: =O19/P9*7 -> 45953.518 | Q20: =SUM(D20:P20) -> 597398.07
B21: Operating Expenses (SG&A) | C21: - | D21: =D6*'Financial Statements'!$F$102 -> 3070.3462 | E21: =E6*'Financial Statements'!$F$102 -> 3070.3462 | F21: =F6*'Financial Statements'!$F$102 -> 3070.3462 | G21: =G6*'Financial Statements'!$F$102 -> 3070.3462 | H21: =H6*'Financial Statements'!$F$102 -> 3070.3462 | I21: =I6*'Financial Statements'!$F$102 -> 3070.3462 | J21: =J6*'Financial Statements'!$F$102 -> 3070.3462 | K21: =K6*'Financial Statements'!$F$102 -> 3070.3462 | ... P21: =P6*'Financial Statements'!$F$102 -> 3070.3462 | Q21: =SUM(D21:P21) -> 39914.5
B22: Interest Expense | C22: - | D22: ='Financial Statements'!$F$100 -> 387.65385 | E22: ='Financial Statements'!$F$100 -> 387.65385 | F22: ='Financial Statements'!$F$100 -> 387.65385 | G22: ='Financial Statements'!$F$100 -> 387.65385 | H22: ='Financial Statements'!$F$100 -> 387.65385 | I22: ='Financial Statements'!$F$100 -> 387.65385 | J22: ='Financial Statements'!$F$100 -> 387.65385 | K22: ='Financial Statements'!$F$100 -> 387.65385 | ... P22: ='Financial Statements'!$F$100 -> 387.65385 | Q22: =SUM(D22:P22) -> 5039.5
B23: Income Tax Payments | C23: - | D23: 0 | E23: 0 | F23: 0 | G23: ='Financial Statements'!$F$20/52*3 -> 2116.2692 | H23: 0 | I23: 0 | J23: ='Financial Statements'!$F$20/52*3 -> 2116.2692 | K23: 0 | L23: 0 | M23: ='Financial Statements'!$F$20/52*3 -> 2116.2692 | N23: 0 | O23: 0 | P23: ='Financial Statements'!$F$20/52*3 -> 2116.2692 | Q23: =SUM(D23:P23) -> 8465.0769
B24: Capital Expenditures | C24: - | D24: =D10 -> 741.23077 | E24: =E10 -> 741.23077 | F24: =F10 -> 741.23077 | G24: =G10 -> 741.23077 | H24: =H10 -> 741.23077 | I24: =I10 -> 741.23077 | J24: =J10 -> 741.23077 | K24: =K10 -> 741.23077 | ... P24: =P10 -> 741.23077 | Q24: =SUM(D24:P24) -> 9636
B25: Total Cash Disbursements | C25: - | D25: =D20+D21+D22+D23+D24 -> 50016.513 | E25: =E20+E21+E22+E23+E24 -> 50181.449 | F25: =F20+F21+F22+F23+F24 -> 50177.01 | G25: =G20+G21+G22+G23+G24 -> 52289.345 | H25: =H20+H21+H22+H23+H24 -> 50169.588 | I25: =I20+I21+I22+I23+I24 -> 50166.497 | J25: =J20+J21+J22+J23+J24 -> 52280.026 | K25: =K20+K21+K22+K23+K24 -> 50161.329 | ... P25: =P20+P21+P22+P23+P24 -> 52269.018 | Q25: =SUM(D25:P25) -> 660453.14
B26: CASH POSITION SUMMARY
B27: Net Cash Flow | D27: =D15-D25 -> -10157.123 | E27: =E15-E25 -> -9172.7229 | F27: =F15-F25 -> -8136.0839 | G27: =G15-G25 -> -9321.416 | H27: =H15-H25 -> -6369.1329 | I27: =I15-I25 -> -5618.363 | J27: =J15-J25 -> -7060.4139 | K27: =K15-K25 -> -4338.672 | ... P27: =P15-P25 -> -4236.9545 | Q27: =SUM(D27:P27) -> -78971.186
B28: Beginning Cash Balance | C28: ='Financial Statements'!F32 -> 322064 | D28: =C28 -> 322064 | E28: =D29 -> 311906.88 | F28: =E29 -> 302734.15 | G28: =F29 -> 294598.07 | H28: =G29 -> 285276.65 | I28: =H29 -> 278907.52 | J28: =I29 -> 273289.16 | K28: =J29 -> 266228.74 | L28: =K29 -> 261890.07 | ... P28: =O29 -> 247329.77 | Q28: =D28 -> 322064
B29: Ending Cash Balance | D29: =D28+D27 -> 311906.88 | E29: =E28+E27 -> 302734.15 | F29: =F28+F27 -> 294598.07 | G29: =G28+G27 -> 285276.65 | H29: =H28+H27 -> 278907.52 | I29: =I28+I27 -> 273289.16 | J29: =J28+J27 -> 266228.74 | K29: =K28+K27 -> 261890.07 | ... P29: =P28+P27 -> 243092.81 | Q29: =P29 -> 243092.81
B30: Minimum Cash Buffer ($15,000K) | C30: 15000 | D30: 15000 | E30: 15000 | F30: 15000 | G30: 15000 | H30: 15000 | I30: 15000 | J30: 15000 | K30: 15000 | L30: 15000 | M30: 15000 | N30: 15000 | O30: 15000 | P30: 15000
B31: Cash Headroom vs. Minimum Buffer | D31: =D29-D30 -> 296906.88 | E31: =E29-E30 -> 287734.15 | F31: =F29-F30 -> 279598.07 | G31: =G29-G30 -> 270276.65 | H31: =H29-H30 -> 263907.52 | I31: =I29-I30 -> 258289.16 | J31: =J29-J30 -> 251228.74 | K31: =K29-K30 -> 246890.07 | ... P31: =P29-P30 -> 228092.81 | Q31: =P31 -> 228092.81

Sheet Scenario 2-Seasonal Pressure
B2: BENCHMARK ELECTRONICS, INC.
B3: SCENARIO 2 — SEASONAL CASH PRESSURE (-8% Revenue, +7 DSO, Higher Inventory) (in $000s)
C4: Opening Balance | D4: Week 1 | E4: Week 2 | F4: Week 3 | G4: Week 4 | H4: Week 5 | I4: Week 6 | J4: Week 7 | K4: Week 8 | L4: Week 9 | M4: Week 10 | N4: Week 11 | O4: Week 12 | P4: Week 13 | Q4: 13-Wk Total
B5: KEY ASSUMPTIONS
B6: Weekly Revenue ($000s) | C6: - | D6: ='Base Case'!D6*0.92 -> 47045.757 | E6: ='Base Case'!E6*0.92 -> 47045.757 | F6: ='Base Case'!F6*0.92 -> 47045.757 | G6: ='Base Case'!G6*0.92 -> 47045.757 | H6: ='Base Case'!H6*0.92 -> 47045.757 | I6: ='Base Case'!I6*0.92 -> 47045.757 | J6: ='Base Case'!J6*0.92 -> 47045.757 | K6: ='Base Case'!K6*0.92 -> 47045.757 | ... P6: ='Base Case'!P6*0.92 -> 47045.757
B7: DSO (days) | C7: - | D7: ='Base Case'!D7+7 -> 60.684117 | E7: ='Base Case'!E7+7 -> 60.684117 | F7: ='Base Case'!F7+7 -> 60.684117 | G7: ='Base Case'!G7+7 -> 60.684117 | H7: ='Base Case'!H7+7 -> 60.684117 | I7: ='Base Case'!I7+7 -> 60.684117 | J7: ='Base Case'!J7+7 -> 60.684117 | K7: ='Base Case'!K7+7 -> 60.684117 | ... P7: ='Base Case'!P7+7 -> 60.684117
B8: DIO (days) | C8: - | D8: ='Base Case'!D8*1.1 -> 81.095792 | E8: ='Base Case'!E8*1.1 -> 81.095792 | F8: ='Base Case'!F8*1.1 -> 81.095792 | G8: ='Base Case'!G8*1.1 -> 81.095792 | H8: ='Base Case'!H8*1.1 -> 81.095792 | I8: ='Base Case'!I8*1.1 -> 81.095792 | J8: ='Base Case'!J8*1.1 -> 81.095792 | K8: ='Base Case'!K8*1.1 -> 81.095792 | ... P8: ='Base Case'!P8*1.1 -> 81.095792
B9: DPO (days) | C9: - | D9: ='Base Case'!D9 -> 61.604571 | E9: ='Base Case'!E9 -> 61.604571 | F9: ='Base Case'!F9 -> 61.604571 | G9: ='Base Case'!G9 -> 61.604571 | H9: ='Base Case'!H9 -> 61.604571 | I9: ='Base Case'!I9 -> 61.604571 | J9: ='Base Case'!J9 -> 61.604571 | K9: ='Base Case'!K9 -> 61.604571 | ... P9: ='Base Case'!P9 -> 61.604571
B10: Weekly CapEx ($000s) | C10: - | D10: ='Base Case'!D10*0.7 -> 518.86154 | E10: ='Base Case'!E10*0.7 -> 518.86154 | F10: ='Base Case'!F10*0.7 -> 518.86154 | G10: ='Base Case'!G10*0.7 -> 518.86154 | H10: ='Base Case'!H10*0.7 -> 518.86154 | I10: ='Base Case'!I10*0.7 -> 518.86154 | J10: ='Base Case'!J10*0.7 -> 518.86154 | K10: ='Base Case'!K10*0.7 -> 518.86154 | ... P10: ='Base Case'!P10*0.7 -> 518.86154
B11: CASH RECEIPTS
B12: Cash Collections from Customers | C12: - | D12: =IF(D7=0,0,C13/D7*7) -> 45114.062 | E12: =IF(E7=0,0,D13/E7*7) -> 45336.886 | F12: =IF(F7=0,0,E13/F7*7) -> 45534.006 | G12: =IF(G7=0,0,F13/G7*7) -> 45708.389 | H12: =IF(H7=0,0,G13/H7*7) -> 45862.656 | I12: =IF(I7=0,0,H13/I7*7) -> 45999.129 | J12: =IF(J7=0,0,I13/J7*7) -> 46119.859 | K12: =IF(K7=0,0,J13/K7*7) -> 46226.662 | ... P12: =IF(P7=0,0,O13/P7*7) -> 46601.956 | Q12: =SUM(D12:P12) -> 598252.24
B13: Accounts Receivable (Ending) | C13: ='Financial Statements'!F34 -> 391101 | D13: =C13+D6-D12 -> 393032.7 | E13: =D13+E6-E12 -> 394741.57 | F13: =E13+F6-F12 -> 396253.32 | G13: =F13+G6-G12 -> 397590.69 | H13: =G13+H6-H12 -> 398773.79 | I13: =H13+I6-I12 -> 399820.41 | J13: =I13+J6-J12 -> 400746.31 | K13: =J13+K6-K12 -> 401565.41 | ... P13: =O13+P6-P12 -> 404443.6 | Q13: =P13 -> 404443.6
B15: Total Cash Receipts | C15: - | D15: =D12 -> 45114.062 | E15: =E12 -> 45336.886 | F15: =F12 -> 45534.006 | G15: =G12 -> 45708.389 | H15: =H12 -> 45862.656 | I15: =I12 -> 45999.129 | J15: =J12 -> 46119.859 | K15: =K12 -> 46226.662 | ... P15: =P12 -> 46601.956 | Q15: =SUM(D15:P15) -> 598252.24
B16: CASH DISBURSEMENTS
B17: Inventory (Ending) | C17: ='Financial Statements'!F36 -> 482544 | D17: =(D6*'Financial Statements'!$F$96)/7*D8 -> 489676.11 | E17: =(E6*'Financial Statements'!$F$96)/7*E8 -> 489676.11 | F17: =(F6*'Financial Statements'!$F$96)/7*F8 -> 489676.11 | G17: =(G6*'Financial Statements'!$F$96)/7*G8 -> 489676.11 | H17: =(H6*'Financial Statements'!$F$96)/7*H8 -> 489676.11 | I17: =(I6*'Financial Statements'!$F$96)/7*I8 -> 489676.11 | J17: =(J6*'Financial Statements'!$F$96)/7*J8 -> 489676.11 | K17: =(K6*'Financial Statements'!$F$96)/7*K8 -> 489676.11 | ... P17: =(P6*'Financial Statements'!$F$96)/7*P8 -> 489676.11 | Q17: =P17 -> 489676.11
B18: Inventory Purchases | C18: - | D18: =(D6*'Financial Statements'!$F$96)+D17-C17 -> 49399.808 | E18: =(E6*'Financial Statements'!$F$96)+E17-D17 -> 42267.702 | F18: =(F6*'Financial Statements'!$F$96)+F17-E17 -> 42267.702 | G18: =(G6*'Financial Statements'!$F$96)+G17-F17 -> 42267.702 | H18: =(H6*'Financial Statements'!$F$96)+H17-G17 -> 42267.702 | I18: =(I6*'Financial Statements'!$F$96)+I17-H17 -> 42267.702 | J18: =(J6*'Financial Statements'!$F$96)+J17-I17 -> 42267.702 | K18: =(K6*'Financial Statements'!$F$96)+K17-J17 -> 42267.702 | ... P18: =(P6*'Financial Statements'!$F$96)+P17-O17 -> 42267.702 | Q18: =SUM(D18:P18) -> 556612.23
B19: Accounts Payable (Ending) | C19: ='Financial Statements'!F48 -> 403222 | D19: =C19+D18-D20 -> 406804.53 | E19: =D19+E18-E20 -> 402847.87 | F19: =E19+F18-F20 -> 399340.8 | G19: =F19+G18-G20 -> 396232.23 | H19: =G19+H18-H20 -> 393476.89 | I19: =H19+I18-I20 -> 391034.62 | J19: =I19+J18-J20 -> 388869.87 | K19: =J19+K18-K20 -> 386951.09 | ... P19: =O19+P18-P20 -> 380172.47 | Q19: =P19 -> 380172.47
B20: AP Payments to Suppliers | C20: - | D20: =C19/D9*7 -> 45817.282 | E20: =D19/E9*7 -> 46224.357 | F20: =E19/F9*7 -> 45774.771 | G20: =F19/G9*7 -> 45376.27 | H20: =G19/H9*7 -> 45023.049 | I20: =H19/I9*7 -> 44709.965 | J20: =I19/J9*7 -> 44432.456 | K20: =J19/K9*7 -> 44186.479 | ... P20: =O19/P9*7 -> 43317.498 | Q20: =SUM(D20:P20) -> 579661.76
B21: Operating Expenses (SG&A) | C21: - | D21: =D6*'Financial Statements'!$F$102 -> 2824.7185 | E21: =E6*'Financial Statements'!$F$102 -> 2824.7185 | F21: =F6*'Financial Statements'!$F$102 -> 2824.7185 | G21: =G6*'Financial Statements'!$F$102 -> 2824.7185 | H21: =H6*'Financial Statements'!$F$102 -> 2824.7185 | I21: =I6*'Financial Statements'!$F$102 -> 2824.7185 | J21: =J6*'Financial Statements'!$F$102 -> 2824.7185 | K21: =K6*'Financial Statements'!$F$102 -> 2824.7185 | ... P21: =P6*'Financial Statements'!$F$102 -> 2824.7185 | Q21: =SUM(D21:P21) -> 36721.34
B22: Interest Expense | C22: - | D22: ='Financial Statements'!$F$100 -> 387.65385 | E22: ='Financial Statements'!$F$100 -> 387.65385 | F22: ='Financial Statements'!$F$100 -> 387.65385 | G22: ='Financial Statements'!$F$100 -> 387.65385 | H22: ='Financial Statements'!$F$100 -> 387.65385 | I22: ='Financial Statements'!$F$100 -> 387.65385 | J22: ='Financial Statements'!$F$100 -> 387.65385 | K22: ='Financial Statements'!$F$100 -> 387.65385 | ... P22: ='Financial Statements'!$F$100 -> 387.65385 | Q22: =SUM(D22:P22) -> 5039.5
B23: Income Tax Payments | C23: - | D23: 0 | E23: 0 | F23: 0 | G23: ='Financial Statements'!$F$20/52*3 -> 2116.2692 | H23: 0 | I23: 0 | J23: ='Financial Statements'!$F$20/52*3 -> 2116.2692 | K23: 0 | L23: 0 | M23: ='Financial Statements'!$F$20/52*3 -> 2116.2692 | N23: 0 | O23: 0 | P23: ='Financial Statements'!$F$20/52*3 -> 2116.2692 | Q23: =SUM(D23:P23) -> 8465.0769
B24: Capital Expenditures | C24: - | D24: =D10 -> 518.86154 | E24: =E10 -> 518.86154 | F24: =F10 -> 518.86154 | G24: =G10 -> 518.86154 | H24: =H10 -> 518.86154 | I24: =I10 -> 518.86154 | J24: =J10 -> 518.86154 | K24: =K10 -> 518.86154 | ... P24: =P10 -> 518.86154 | Q24: =SUM(D24:P24) -> 6745.2
B25: Total Cash Disbursements | C25: - | D25: =D20+D21+D22+D23+D24 -> 49548.516 | E25: =E20+E21+E22+E23+E24 -> 49955.591 | F25: =F20+F21+F22+F23+F24 -> 49506.004 | G25: =G20+G21+G22+G23+G24 -> 51223.773 | H25: =H20+H21+H22+H23+H24 -> 48754.283 | I25: =I20+I21+I22+I23+I24 -> 48441.199 | J25: =J20+J21+J22+J23+J24 -> 50279.959 | K25: =K20+K21+K22+K23+K24 -> 47917.713 | ... P25: =P20+P21+P22+P23+P24 -> 49165.001 | Q25: =SUM(D25:P25) -> 636632.88
B26: CASH POSITION SUMMARY
B27: Net Cash Flow | D27: =D15-D25 -> -4434.4543 | E27: =E15-E25 -> -4618.7055 | F27: =F15-F25 -> -3971.9981 | G27: =G15-G25 -> -5515.3837 | H27: =H15-H25 -> -2891.627 | I27: =I15-I25 -> -2442.0702 | J27: =J15-J25 -> -4160.1 | K27: =K15-K25 -> -1691.0506 | ... P27: =P15-P25 -> -2563.0444 | Q27: =SUM(D27:P27) -> -38380.632
B28: Beginning Cash Balance | C28: ='Financial Statements'!F32 -> 322064 | D28: =C28 -> 322064 | E28: =D29 -> 317629.55 | F28: =E29 -> 313010.84 | G28: =F29 -> 309038.84 | H28: =G29 -> 303523.46 | I28: =H29 -> 300631.83 | J28: =I29 -> 298189.76 | K28: =J29 -> 294029.66 | L28: =K29 -> 292338.61 | ... P28: =O29 -> 286246.41 | Q28: =D28 -> 322064
B29: Ending Cash Balance | D29: =D28+D27 -> 317629.55 | E29: =E28+E27 -> 313010.84 | F29: =F28+F27 -> 309038.84 | G29: =G28+G27 -> 303523.46 | H29: =H28+H27 -> 300631.83 | I29: =I28+I27 -> 298189.76 | J29: =J28+J27 -> 294029.66 | K29: =K28+K27 -> 292338.61 | ... P29: =P28+P27 -> 283683.37 | Q29: =P29 -> 283683.37
B30: Minimum Cash Buffer ($15,000K) | C30: 15000 | D30: 15000 | E30: 15000 | F30: 15000 | G30: 15000 | H30: 15000 | I30: 15000 | J30: 15000 | K30: 15000 | L30: 15000 | M30: 15000 | N30: 15000 | O30: 15000 | P30: 15000
B31: Cash Headroom vs. Minimum Buffer | D31: =D29-D30 -> 302629.55 | E31: =E29-E30 -> 298010.84 | F31: =F29-F30 -> 294038.84 | G31: =G29-G30 -> 288523.46 | H31: =H29-H30 -> 285631.83 | I31: =I29-I30 -> 283189.76 | J31: =J29-J30 -> 279029.66 | K31: =K29-K30 -> 277338.61 | ... P31: =P29-P30 -> 268683.37 | Q31: =P31 -> 268683.37

Sheet Scenario 3-Process Improvement
B2: BENCHMARK ELECTRONICS, INC.
B3: SCENARIO 3 — PROCESS IMPROVEMENT (-8 DSO Days, +5 DPO Days) (in $000s)
C4: Opening Balance | D4: Week 1 | E4: Week 2 | F4: Week 3 | G4: Week 4 | H4: Week 5 | I4: Week 6 | J4: Week 7 | K4: Week 8 | L4: Week 9 | M4: Week 10 | N4: Week 11 | O4: Week 12 | P4: Week 13 | Q4: 13-Wk Total
B5: KEY ASSUMPTIONS
B6: Weekly Revenue ($000s) | C6: - | D6: ='Base Case'!D6 -> 51136.692 | E6: ='Base Case'!E6 -> 51136.692 | F6: ='Base Case'!F6 -> 51136.692 | G6: ='Base Case'!G6 -> 51136.692 | H6: ='Base Case'!H6 -> 51136.692 | I6: ='Base Case'!I6 -> 51136.692 | J6: ='Base Case'!J6 -> 51136.692 | K6: ='Base Case'!K6 -> 51136.692 | ... P6: ='Base Case'!P6 -> 51136.692
B7: DSO (days) | C7: - | D7: ='Base Case'!D7-8 -> 45.684117 | E7: ='Base Case'!E7-8 -> 45.684117 | F7: ='Base Case'!F7-8 -> 45.684117 | G7: ='Base Case'!G7-8 -> 45.684117 | H7: ='Base Case'!H7-8 -> 45.684117 | I7: ='Base Case'!I7-8 -> 45.684117 | J7: ='Base Case'!J7-8 -> 45.684117 | K7: ='Base Case'!K7-8 -> 45.684117 | ... P7: ='Base Case'!P7-8 -> 45.684117
B8: DIO (days) | C8: - | D8: ='Base Case'!D8 -> 73.723448 | E8: ='Base Case'!E8 -> 73.723448 | F8: ='Base Case'!F8 -> 73.723448 | G8: ='Base Case'!G8 -> 73.723448 | H8: ='Base Case'!H8 -> 73.723448 | I8: ='Base Case'!I8 -> 73.723448 | J8: ='Base Case'!J8 -> 73.723448 | K8: ='Base Case'!K8 -> 73.723448 | ... P8: ='Base Case'!P8 -> 73.723448
B9: DPO (days) | C9: - | D9: ='Base Case'!D9+5 -> 66.604571 | E9: ='Base Case'!E9+5 -> 66.604571 | F9: ='Base Case'!F9+5 -> 66.604571 | G9: ='Base Case'!G9+5 -> 66.604571 | H9: ='Base Case'!H9+5 -> 66.604571 | I9: ='Base Case'!I9+5 -> 66.604571 | J9: ='Base Case'!J9+5 -> 66.604571 | K9: ='Base Case'!K9+5 -> 66.604571 | ... P9: ='Base Case'!P9+5 -> 66.604571
B10: Weekly CapEx ($000s) | C10: - | D10: ='Base Case'!D10 -> 741.23077 | E10: ='Base Case'!E10 -> 741.23077 | F10: ='Base Case'!F10 -> 741.23077 | G10: ='Base Case'!G10 -> 741.23077 | H10: ='Base Case'!H10 -> 741.23077 | I10: ='Base Case'!I10 -> 741.23077 | J10: ='Base Case'!J10 -> 741.23077 | K10: ='Base Case'!K10 -> 741.23077 | ... P10: ='Base Case'!P10 -> 741.23077
B11: CASH RECEIPTS
B12: Cash Collections from Customers | C12: - | D12: =IF(D7=0,0,C13/D7*7) -> 59926.889 | E12: =IF(E7=0,0,D13/E7*7) -> 58580.001 | F12: =IF(F7=0,0,E13/F7*7) -> 57439.492 | G12: =IF(G7=0,0,F13/G7*7) -> 56473.738 | H12: =IF(H7=0,0,G13/H7*7) -> 55655.963 | I12: =IF(I7=0,0,H13/I7*7) -> 54963.493 | J12: =IF(J7=0,0,I13/J7*7) -> 54377.127 | K12: =IF(K7=0,0,J13/K7*7) -> 53880.608 | ... P12: =IF(P7=0,0,O13/P7*7) -> 52331.252 | Q12: =SUM(D12:P12) -> 715542.98
B13: Accounts Receivable (Ending) | C13: ='Financial Statements'!F34 -> 391101 | D13: =C13+D6-D12 -> 382310.8 | E13: =D13+E6-E12 -> 374867.49 | F13: =E13+F6-F12 -> 368564.7 | G13: =F13+G6-G12 -> 363227.65 | H13: =G13+H6-H12 -> 358708.38 | I13: =H13+I6-I12 -> 354881.58 | J13: =I13+J6-J12 -> 351641.14 | K13: =J13+K6-K12 -> 348897.23 | ... P13: =O13+P6-P12 -> 340335.02 | Q13: =P13 -> 340335.02
B15: Total Cash Receipts | C15: - | D15: =D12 -> 59926.889 | E15: =E12 -> 58580.001 | F15: =F12 -> 57439.492 | G15: =G12 -> 56473.738 | H15: =H12 -> 55655.963 | I15: =I12 -> 54963.493 | J15: =J12 -> 54377.127 | K15: =K12 -> 53880.608 | ... P15: =P12 -> 52331.252 | Q15: =SUM(D15:P15) -> 715542.98
B16: CASH DISBURSEMENTS
B17: Inventory (Ending) | C17: ='Financial Statements'!F36 -> 482544 | D17: =(D6*'Financial Statements'!$F$96)/7*D8 -> 483869.67 | E17: =(E6*'Financial Statements'!$F$96)/7*E8 -> 483869.67 | F17: =(F6*'Financial Statements'!$F$96)/7*F8 -> 483869.67 | G17: =(G6*'Financial Statements'!$F$96)/7*G8 -> 483869.67 | H17: =(H6*'Financial Statements'!$F$96)/7*H8 -> 483869.67 | I17: =(I6*'Financial Statements'!$F$96)/7*I8 -> 483869.67 | J17: =(J6*'Financial Statements'!$F$96)/7*J8 -> 483869.67 | K17: =(K6*'Financial Statements'!$F$96)/7*K8 -> 483869.67 | ... P17: =(P6*'Financial Statements'!$F$96)/7*P8 -> 483869.67 | Q17: =P17 -> 483869.67
B18: Inventory Purchases | C18: - | D18: =(D6*'Financial Statements'!$F$96)+D17-C17 -> 47268.824 | E18: =(E6*'Financial Statements'!$F$96)+E17-D17 -> 45943.154 | F18: =(F6*'Financial Statements'!$F$96)+F17-E17 -> 45943.154 | G18: =(G6*'Financial Statements'!$F$96)+G17-F17 -> 45943.154 | H18: =(H6*'Financial Statements'!$F$96)+H17-G17 -> 45943.154 | I18: =(I6*'Financial Statements'!$F$96)+I17-H17 -> 45943.154 | J18: =(J6*'Financial Statements'!$F$96)+J17-I17 -> 45943.154 | K18: =(K6*'Financial Statements'!$F$96)+K17-J17 -> 45943.154 | ... P18: =(P6*'Financial Statements'!$F$96)+P17-O17 -> 45943.154 | Q18: =SUM(D18:P18) -> 598586.67
B19: Accounts Payable (Ending) | C19: ='Financial Statements'!F48 -> 403222 | D19: =C19+D18-D20 -> 408113.04 | E19: =D19+E18-E20 -> 411164.38 | F19: =E19+F18-F20 -> 413895.02 | G19: =F19+G18-G20 -> 416338.68 | H19: =G19+H18-H20 -> 418525.52 | I19: =H19+I18-I20 -> 420482.52 | J19: =I19+J18-J20 -> 422233.85 | K19: =J19+K18-K20 -> 423801.11 | ... P19: =O19+P18-P20 -> 429486.76 | Q19: =P19 -> 429486.76
B20: AP Payments to Suppliers | C20: - | D20: =C19/D9*7 -> 42377.782 | E20: =D19/E9*7 -> 42891.821 | F20: =E19/F9*7 -> 43212.509 | G20: =F19/G9*7 -> 43499.494 | H20: =G19/H9*7 -> 43756.318 | I20: =H19/I9*7 -> 43986.15 | J20: =I19/J9*7 -> 44191.827 | K20: =J19/K9*7 -> 44375.887 | ... P20: =O19/P9*7 -> 45043.614 | Q20: =SUM(D20:P20) -> 572321.91
B21: Operating Expenses (SG&A) | C21: - | D21: =D6*'Financial Statements'!$F$102 -> 3070.3462 | E21: =E6*'Financial Statements'!$F$102 -> 3070.3462 | F21: =F6*'Financial Statements'!$F$102 -> 3070.3462 | G21: =G6*'Financial Statements'!$F$102 -> 3070.3462 | H21: =H6*'Financial Statements'!$F$102 -> 3070.3462 | I21: =I6*'Financial Statements'!$F$102 -> 3070.3462 | J21: =J6*'Financial Statements'!$F$102 -> 3070.3462 | K21: =K6*'Financial Statements'!$F$102 -> 3070.3462 | ... P21: =P6*'Financial Statements'!$F$102 -> 3070.3462 | Q21: =SUM(D21:P21) -> 39914.5
B22: Interest Expense | C22: - | D22: ='Financial Statements'!$F$100 -> 387.65385 | E22: ='Financial Statements'!$F$100 -> 387.65385 | F22: ='Financial Statements'!$F$100 -> 387.65385 | G22: ='Financial Statements'!$F$100 -> 387.65385 | H22: ='Financial Statements'!$F$100 -> 387.65385 | I22: ='Financial Statements'!$F$100 -> 387.65385 | J22: ='Financial Statements'!$F$100 -> 387.65385 | K22: ='Financial Statements'!$F$100 -> 387.65385 | ... P22: ='Financial Statements'!$F$100 -> 387.65385 | Q22: =SUM(D22:P22) -> 5039.5
B23: Income Tax Payments | C23: - | D23: 0 | E23: 0 | F23: 0 | G23: ='Financial Statements'!$F$20/52*3 -> 2116.2692 | H23: 0 | I23: 0 | J23: ='Financial Statements'!$F$20/52*3 -> 2116.2692 | K23: 0 | L23: 0 | M23: ='Financial Statements'!$F$20/52*3 -> 2116.2692 | N23: 0 | O23: 0 | P23: ='Financial Statements'!$F$20/52*3 -> 2116.2692 | Q23: =SUM(D23:P23) -> 8465.0769
B24: Capital Expenditures | C24: - | D24: =D10 -> 741.23077 | E24: =E10 -> 741.23077 | F24: =F10 -> 741.23077 | G24: =G10 -> 741.23077 | H24: =H10 -> 741.23077 | I24: =I10 -> 741.23077 | J24: =J10 -> 741.23077 | K24: =K10 -> 741.23077 | ... P24: =P10 -> 741.23077 | Q24: =SUM(D24:P24) -> 9636
B25: Total Cash Disbursements | C25: - | D25: =D20+D21+D22+D23+D24 -> 46577.013 | E25: =E20+E21+E22+E23+E24 -> 47091.051 | F25: =F20+F21+F22+F23+F24 -> 47411.74 | G25: =G20+G21+G22+G23+G24 -> 49814.994 | H25: =H20+H21+H22+H23+H24 -> 47955.548 | I25: =I20+I21+I22+I23+I24 -> 48185.38 | J25: =J20+J21+J22+J23+J24 -> 50507.327 | K25: =K20+K21+K22+K23+K24 -> 48575.118 | ... P25: =P20+P21+P22+P23+P24 -> 51359.114 | Q25: =SUM(D25:P25) -> 635376.98
B26: CASH POSITION SUMMARY
B27: Net Cash Flow | D27: =D15-D25 -> 13349.876 | E27: =E15-E25 -> 11488.95 | F27: =F15-F25 -> 10027.752 | G27: =G15-G25 -> 6658.744 | H27: =H15-H25 -> 7700.415 | I27: =I15-I25 -> 6778.1127 | J27: =J15-J25 -> 3869.8006 | K27: =K15-K25 -> 5305.4898 | ... P27: =P15-P25 -> 972.13863 | Q27: =SUM(D27:P27) -> 80165.996
B28: Beginning Cash Balance | C28: ='Financial Statements'!F32 -> 322064 | D28: =C28 -> 322064 | E28: =D29 -> 335413.88 | F28: =E29 -> 346902.83 | G28: =F29 -> 356930.58 | H28: =G29 -> 363589.32 | I28: =H29 -> 371289.74 | J28: =I29 -> 378067.85 | K28: =J29 -> 381937.65 | L28: =K29 -> 387243.14 | ... P28: =O29 -> 401257.86 | Q28: =D28 -> 322064
B29: Ending Cash Balance | D29: =D28+D27 -> 335413.88 | E29: =E28+E27 -> 346902.83 | F29: =F28+F27 -> 356930.58 | G29: =G28+G27 -> 363589.32 | H29: =H28+H27 -> 371289.74 | I29: =I28+I27 -> 378067.85 | J29: =J28+J27 -> 381937.65 | K29: =K28+K27 -> 387243.14 | ... P29: =P28+P27 -> 402230 | Q29: =P29 -> 402230
B30: Minimum Cash Buffer ($15,000K) | C30: 15000 | D30: 15000 | E30: 15000 | F30: 15000 | G30: 15000 | H30: 15000 | I30: 15000 | J30: 15000 | K30: 15000 | L30: 15000 | M30: 15000 | N30: 15000 | O30: 15000 | P30: 15000
B31: Cash Headroom vs. Minimum Buffer | D31: =D29-D30 -> 320413.88 | E31: =E29-E30 -> 331902.83 | F31: =F29-F30 -> 341930.58 | G31: =G29-G30 -> 348589.32 | H31: =H29-H30 -> 356289.74 | I31: =I29-I30 -> 363067.85 | J31: =J29-J30 -> 366937.65 | K31: =K29-K30 -> 372243.14 | ... P31: =P29-P30 -> 387230 | Q31: =P31 -> 387230

Sheet Scenario Comparison
B2: BENCHMARK ELECTRONICS, INC.— SCENARIO COMPARISON SUMMARY
B3: 13-Week Cash Flow Forecast | All figures in USD thousands ($000s)
C4: Base Case | D4: Scenario 1 Slow Collections | E4: Scenario 2 Seasonal Pressure | F4: Scenario 3 Process Improvement | G4: Key Insight
B5: Beginning Cash Balance | C5: ='Base Case'!C28 -> 322064 | D5: ='Scenario 1-Slow Collections'!C28 -> 322064 | E5: ='Scenario 2-Seasonal Pressure'!C28 -> 322064 | F5: ='Scenario 3-Process Improvement'!D28 -> 322064 | G5: All Scenarios start from FY 2025 year-end cash
B6: 13-Week Total Collections | C6: ='Base Case'!Q15 -> 663877.29 | D6: =SUM('Scenario 1-Slow Collections'!D15:P15) -> 581481.96 | E6: =SUM('Scenario 2-Seasonal Pressure'!D15:P15) -> 598252.24 | F6: =SUM('Scenario 3-Process Improvement'!D15:P15) -> 715542.98 | G6: Higher = better liquidity from customers
B7: 13-Week Total Disbursements | C7: ='Base Case'!Q25 -> 660453.14 | D7: =SUM('Scenario 1-Slow Collections'!D25:P25) -> 660453.14 | E7: =SUM('Scenario 2-Seasonal Pressure'!D25:P25) -> 636632.88 | F7: =SUM('Scenario 3-Process Improvement'!D25:P25) -> 635376.98 | G7: Lower = less cash going out
B8: Net Cash Flow (13 Weeks) | C8: ='Base Case'!Q27 -> 3424.1425 | D8: =SUM('Scenario 1-Slow Collections'!D27:P27) -> -78971.186 | E8: =SUM('Scenario 2-Seasonal Pressure'!D27:P27) -> -38380.632 | F8: =SUM('Scenario 3-Process Improvement'!D27:P27) -> 80165.996 | G8: Cumulative net cash generated
B9: Ending Cash Balance (Wk 13) | C9: ='Base Case'!Q29 -> 325488.14 | D9: ='Scenario 1-Slow Collections'!P29 -> 243092.81 | E9: ='Scenario 2-Seasonal Pressure'!P29 -> 283683.37 | F9: ='Scenario 3-Process Improvement'!P29 -> 402230 | G9: Final cash position vs. $15M minimum buffer
B10: Ending Cash vs. Base | C10: =C9-$C$9 -> 0 | D10: =D9-$C$9 -> -82395.329 | E10: =E9-$C$9 -> -41804.775 | F10: =F9-$C$9 -> 76741.853 | G10: Isolates the cash impact of each scenario's assumptions
B11: Minimum Cash Headroom | C11: =MIN('Base Case'!D31:P31) -> 308044.08 | D11: =MIN('Scenario 1-Slow Collections'!D31:P31) -> 228092.81 | E11: =MIN('Scenario 2-Seasonal Pressure'!D31:P31) -> 268683.37 | F11: =MIN('Scenario 3-Process Improvement'!D31:P31) -> 320413.88 | G11: Tightest point vs. $15M buffer
B13: Key Findings and Analytics Insights
B14: 1. DSO is the primary cash lever.
B15: A 15-day increase in DSO (Scenario 1) reduces ending cash by $82.4M over 13 weeks, roughly $5.5M for every day customers take longer to pay. That is twice the impact of an 8% revenue decline (Scenario 2). AR management is not just an administrative function; it is a direct liquidity risk. In manufacturing services, where customer concentration is high and payment terms are negotiated, even modest slippage in collections creates measurable cash pressure.
B16: 2. Seasonal softness hits collections faster than costs.
B17: In Scenario 2, collections fall 9.9% ($65.6M) while disbursements fall only 3.6% ($23.8M), reducing ending cash by $41.8M. Inventory still rises about $5.8M despite lower sales because DIO extends 10%, so purchases do not shrink as fast as revenue. This is characteristic of electronics manufacturing, where build schedules lag demand signals by several weeks.
B18: 3. Process improvement has a quantifiable ROI.
B19: Scenario 3 shows that an 8-day DSO reduction and 5-day DPO extension generate $76.7M of additional cash over 13 weeks: $51.7M from faster collections and $25.1M from slower supplier payments. This nearly offsets the entire Scenario 1 downside and provides a financial justification for e-invoicing, automated dunning, and AP scheduling improvements.
B20: 4. Benchmark maintains adequate liquidity in all scenarios.
B21: With $322.1M in opening cash, the lowest point in any scenario is $228.1M of headroom above the $15M minimum buffer (Scenario 1). The question for management is not solvency but optimization: how much cash is tied up in working capital that could be released through faster collections and better payment terms.
